Workbook

Sheet Advertising
A1: ID | B1: Network URL [URL] | C1: Date of Analysis [DATE] | D1: Reviewer [Name] | E1: Date of Selling/Sharing (Buying/Collecting) Doublechecked by SZ [DATE] | F1: Crosslisted [0, 1] | G1: Crosslisted Category [Category Name] | H1: Targeted Advertising [0, 1] | I1: Evidence | J1: Profiling [0, 1] | K1: Evidence | L1: Selling/Sharing (Buying/Collecting) [0, 1] | M1: Evidence | N1: Setting: To Opt Out [0, 1] | O1: Evidence | P1: Selling By Default [0, 1] | Q1: Evidence | R1: Sign of Not Selling [0, 1] | S1: What is it [How it opts out] | T1: Evidence | U1: Relevant URLs [URL]
A2: 11 | B2: http://www.activeconversion.com/ | C2: 45237 | D2: Sophie | E2: 45529 | F2: 0 | H2: 1 | I2: We may collect information about you from other sources, including our partners, and combine this information with the Personal Information provided by you. This helps us update our records, identify new customers, create tailored advertising, and analyze overall trends so we may facilitate and provide relevant content, event promotions, and services that may be of interest to you. | J2: 1 | K2: We may collect information about you from other sources, including our partners, and combine this information with the Personal Information provided by you. This helps us update our records, identify new customers, create tailored advertising, and analyze overall trends so we may facilitate and provide relevant content, event promotions, and services that may be of interest to you. | L2: 1 | M2: We may collect information about you from other sources, including our partners, and combine this information with the Personal Information provided by you. This helps us update our records, identify new customers, create tailored advertising, and analyze overall trends so we may facilitate and provide relevant content, event promotions, and services that may be of interest to you. Our platforms rely heavily on the sharing and management of data. As such, we have worked diligently to ensure we comply with regulations across the globe including GDPR, PIPEDA, and the California Privacy Rights Act. | N2: 0 | P2: 1 | R2: 0 | U2: https://activeiq.co/privacy-data/ https://activeiq.co/privacy/
A3: 22 | B3: https://adaptmx.com/ | C3: 45227 | D3: Sophie | E3: 45529 | F3: 1 | G3: FingerprintInv | H3: 1 | I3: We use the information we collect to provide and improve Monet Engine Services, including for the following purposes: Serving ads: Allowing publishers to offer advertising inventory in their mobile apps and websites, and advertisers to bid on and fill that inventory. | J3: 1 | K3: When you interact with a website or app that uses the Monet Engine Services, we may collect information about your device and the ads you view or click. The Monet Engine Services are designed to avoid collecting information that identifies you personally, such as your name, address, or email address. | L3: 1 | M3: We share with advertiser customers information so that they can decide whether to bid on ad inventory or serve an advertisement and choose the best ad for that device. Monet Engine Customers are obligated to use the information they receive in compliance with applicable laws and regulations. ... The California Consumer Privacy Act (CCPA) requires to disclose to California residents below ... The categories of information that we “sell” or discloses to third parties ... Information as to how you can access, delete, or opt-out of the sale of your personal information. | N3: 1 | O3: Form that's a link to One Trust | P3: 1 | R3: 0 | S3: Nothing on the actual website | U3: https://adaptmx.com/privacy-policy/
A4: 59 | B4: https://adman.gr/ | C4: 45228 | D4: Oliver | E4: 45529 | F4: 0 | H4: 1 | I4: "ADMAN and GRXchange may use data it processes to limit the number of times a user sees a particular ad, to customize or personalize ads based on the context of the page or location(country) of the user, to determine the effectiveness of the ads, and for identifying fraudulent activity." | J4: 1 | K4: "ADMAN and GRXchange may use data it processes to limit the number of times a user sees a particular ad, to customize or personalize ads based on the context of the page or location(country) of the user, to determine the effectiveness of the ads, and for identifying fraudulent activity." | L4: 1 | M4: ADMAN and GRXchange may use data it processes to limit the number of times a user sees a particular ad, to customize or personalize ads based on the context of the page or location(country) of the user, to determine the effectiveness of the ads, and for identifying fraudulent activity. | N4: 1 | P4: 1 | R4: 0 | U4: https://adman.gr/privacy
A5: 71 | B5: http://www.admedia.com/ | C5: 45185 | D5: Oliver | E5: 45529 | F5: 0 | H5: 1 | I5: "These cookies collect information about your browsing habits in order to make advertising more relevant to you and your interests." | J5: 1 | K5: "At times, we may find it necessary to use personally identifiable information as a means to keep you informed of other possible products and/or services that may be available to you from www.admedia.com" | L5: 1 | M5: "Marketing or Advertising Cookies : These cookies collect information about your browsing habits in order to make advertising more relevant to you and your interests." ... Under this Privacy Policy, and by law if you are a resident of California, you have the following rights: ... The right to say no to the sale of Personal Data. You also have the right to ask AdMedia not to sell your Personal Data to third parties. You can submit such a request by visiting our "Do Not Sell My Personal Information" section or web page. | N5: 1 | O5: "opt out of the use of your personal information for interest-based advertising purposes and these potential sales as defined under CCPA law, you may do so by emailing legal@admedia.com" | P5: 1 | Q5: Proof by existence of opt out mechanism | R5: 0 | S5: Unclear, especially when done through email | U5: https://admedia.com/privacy/
A6: 88 | B6: http://www.adperfect.com/ | C6: 45230 | D6: Oliver | E6: 45529 | F6: 0 | H6: 1 | I6: "we collect and store personal information from individuals who visit our Customers’ websites and interact with our platform for purposes of creating an obituary or classified advertisement" | J6: 1 | K6: "Categories of personal information that we may collect automatically when you use the Services include" | L6: 1 | M6: AdPerfect is a software-as-a-service provider that licenses the use of its obituary and classified advertisement creation tool to newspapers (our “Customers”). As part of providing these Services, we collect and store personal information from individuals who visit our Customers’ websites and interact with our platform for purposes of creating an obituary or classified advertisement (“End Users”). ... We do not sell personal information. ... As a California resident, you have the following rights with respect to your personal information: You have the right to request to know about personal information collected, disclosed, or sold. | N6: 0 | P6: 1 | R6: 0 | U6: https://www.adperfect.com/privacy-policy
A7: 113 | B7: https://www.adtheorent.com/ | C7: 45184 | D7: Oliver | E7: 45529 | F7: 0 | H7: 1 | I7: "AdTheorent is a publicly traded (NASDAQ-listed) digital ad network and DSP which uses machine learning, data science and related technology to assist advertisers and advertising agencies in their efforts to deliver targeted and useful digital advertisements to consumers." | J7: 1 | K7: "As such, we do engage in “profiling.”" | L7: 1 | M7: AdTheorent is not a "seller" of Personal Information but AdTheorent is a downstream "user" or certain Personal Information provided by publishers. | N7: 1 | O7: any User is free to Opt-Out of any such future practice or use of User-specific behavioral, geocoding or interest-based targeted advertising by clicking here. | P7: 1 | Q7: Proof by existence of opt out mechanism | R7: 1 | S7: It places a unique cookie with your user ID that stops targeted advertising | T7: https://opt-out.adentifi.com/ | U7: https://opt-out.adentifi.com/ https://www.adtheorent.com/privacy-policy
A8: 121 | B8: http://adventive.com/ | C8: 45188 | D8: Sophie | E8: 45529 | F8: 0 | H8: 1 | I8: For example, we may combine information entered on the Adventive sales form with information received from a third-party sales integration vendor to enhance our ability to market our services to Customers or potential customers. | J8: 1 | K8: This information may include, but is not limited too, Internet Protocol (IP) addresses, system configuration information, referring URLs, locale and language settings. | L8: 0 | M8: Effective January 1, 2020, all agreement(s) entered into by and between Adventive, Inc. and You addressing our processing of Personal Information on your company’s behalf (the “Agreements”) are hereby amended to clarify Adventive as a Service Provider | N8: 1 | O8: you may opt-out by clicking here to access tools from the Network Advertising Initiative | P8: 1 | Q8: Proof by existence of optout | R8: 0 | U8: https://adventive.com/legal/privacy-policy/ https://adventive.com/legal/ccpa/ https://static.adventivecdn.com/legal/2020-01-01-Adventive-CCPA-Amendment.pdf
A9: 182 | B9: http://www.audience2media.com/ | C9: 45233 | D9: Oliver | E9: 45529 | F9: 0 | H9: 1 | I9: "We further create behavioural categories by simply identifying which websites' online users visit" | J9: 1 | K9: " create real time interests of the anonymous online user, based on their web surfing habits." | L9: 1 | M9: Audience2Media is an Audience Targeting Platform (KRYPTON) & Influencer Marketing Platform (IMPACT). Audience2Media specialises in targeting online users by displaying relevant adverts on specific websites a mobile apps. ... Publishers are websites that we source to collect user data, which allows Audience2Media to serve relevant ads to online users. | N9: 1 | P9: 1 | R9: 0 | U9: https://www.audience2media.com/privacy
A10: 184 | B10: https://audigent.com/ | C10: 45228 | D10: Sophie | E10: 45529 | F10: 0 | H10: 1 | I10: The Platform ingests information, including personal information, provided by clients, data providers, partners, and other third-party sources to allow clients to use such data to target ads and/or to leverage other Data Functions. | J10: 1 | K10: we may collect information about you and your device. While this information does not enable us to directly identify you or other users (we do not know your name or contact information), that information may be considered “personal data” or “personal information” under applicable privacy laws. | L10: 1 | M10: Right to opt out of selling or sharing. At the time this Platform Privacy Policy was last updated, we (1) SELL personal information; and (2) we SHARE personal information for the purpose of cross-context behavioral advertising. | N10: 1 | O10: To opt out of interest-based advertising on the Platform, go to Audigent’s Privacy Center. | P10: 1 | R10: 1 | S10: adgt | U10: https://audigent.com/platform-privacy-policy
A11: 205 | B11: http://beachfront.com/ | C11: 45225 | D11: Oliver | E11: 45529 | F11: 0 | H11: 1 | I11: "We utilize cookies to store user data that can aid in targeting of advertisements" | J11: 0 | L11: 1 | M11: We are not in the business of collecting, using, or selling consumer data; however we do offer technologies to advertisers and publishers that allows them to sell and purchase space or digital advertisements to try and ensure that the audience they desire sees their ads and that the advertising itself is delivered and the performance of the advertising can be analyzed. Since we share personal information collected through the Services for commercial purposes and this sharing enables BFM to generate valuable consideration, some of these categories of personal information could be deemed as “sold” in the past twelve months. | N11: 1 | P11: 1 | R11: 0 | U11: https://www.beachfront.com/privacy-policy https://www.beachfront.com/beachfront-media-llc-privacy-rights-notice
A12: 213 | B12: https://bidmind.com | C12: 45188 | D12: Sophie | E12: 45529 | F12: 0 | H12: 1 | I12: We also use User’s Advertising/Device ID and the information associated with User’s device Advertising/Device ID over time ... to enhance our services and to select Bidmind Clients’ ads that are most likely to be of interest to User. | J12: 1 | K12: Bidmind servers may receive and store an advertising identifier (“Advertising ID”) or device identifier (“Device ID”), either of them is a pseudonymous number that is associated with user of our Client | L12: 1 | M12: In some cases, based on data we collect ourselves, or receive from our Clients or data partners (e.g. Audiences as defined below), we infer within a reasonable probability that another browser or device should be associated with the same Adverting/Device ID. ... We will share the information collected about you as described above for various business purposes, with service providers and with third parties, including our Clients. The table below describes how and with whom we share or disclose personal information, and whether we believe we have sold or shared a particular category of information in the prior 12 months. | N12: 1 | O12: You can always opt-out of the serving of targeted advertising by Bidmind by clicking here. | P12: 1 | Q12: Proof by existence of optout | R12: 0 | S12: have a website to put in your information | U12: https://bidmind.com/privacy-policy/
A13: 218 | B13: http://www.bidvertiser.com/ | C13: 45213 | D13: Oliver | E13: 45529 | F13: 0 | H13: 1 | I13: "To enable advertisements delivery, including behavioral advertising" | J13: 1 | K13: "These cookies may also be used to enable third-party advertising networks to deliver ads that may be relevant to you based upon your activities or interests." | L13: 1 | M13: Get exactly the traffic you want - when you want. Geo, device, OS, browser, ISP, carrier, subid, time-of-day, channel, contextual and more. | N13: 0 | P13: 1 | R13: 0 | U13: https://www.bidvertiser.com/ https://www.bidvertiser.com/privacy/
A14: 227 | B14: https://blockthrough.com/ | C14: 45230 | D14: Oliver | E14: 45529 | F14: 0 | H14: 1 | I14: "Other cookies also enable us to track and target the interests of our users to enhance the experience on our Websites." | J14: 1 | K14: "During your visit to Blockthrough.com, we collect certain information automatically from your device" | L14: 0 | M14: When processing Personal Information on behalf of our customers, Blockthrough is acting as the “data processor” and the customer is the “data controller”. | N14: 0 | P14: 1 | R14: 0 | U14: https://blockthrough.com/privacy-policy/
A15: 228 | B15: http://www.blogher.com/ | C15: 45188 | D15: Sophie | E15: 45529 | F15: 0 | H15: 0 | J15: 1 | K15: Demographic, statistical and interest information such as interests, lifestyle information, hobbies, health and wellness information, your age, date of birth, gender, income and other personal finance information, sexual orientation, and race or ethnicity* (to the extent permitted by and in accordance with applicable law. | L15: 1 | M15: California, Colorado, Connecticut, and Virginia residents may opt out of the “sale” of their personal information or processing or sharing of your information for online targeted advertising purposes. We sell or share certain of your information to third parties that may directly provide you with offers and promotions and opportunities that may be of interest to you. | N15: 1 | O15: You may have the ability to accept or decline (or opt out of) certain cookies for analytics & targeted advertising on our Services depending on your jurisdiction. | P15: 1 | Q15: Proof by existence of optout | R15: 0 | U15: https://www.pmc.com/privacy-policy
A16: 265 | B16: https://carts.guru/ | C16: 45188 | D16: Sophie | E16: 45529 | F16: 1 | G16: FingerprintInv | H16: 1 | I16: Send Visitors information for marketing purposes (where it is in accordance with Visitors’ communication preferences); | J16: 1 | K16: We may ask Visitors to provide specific information set out in an online inquiry form (for example, name, contact details, company name, country, monthly visitors volume, billing information, profile information etc). | L16: 1 | M16: We may also share personal information collected through the Services with third party companies so that they may offer products and services that We believe will be of interest to You. We may also share personal information with third party advertising-serving companies to better target the adverts and other content displayed on Our site and to provide offers We think may be of interest to You. You may opt-out of disclosure of Your information to third parties for direct marketing purposes – see the Choice and Opt-Out section below. ... California law provides that California residents have a right to request that businesses tell them how their personally identifiable information has been shared with third parties for those third parties’ direct marketing purposes. However, there is an exception to this requirement for businesses that have adopted and disclosed, in their privacy policy, a policy of not disclosing a person’s personally identifiable information to third parties for those third parties’ direct marketing purposes if that person has exercised an option to opt-out of the disclosure of their personally identifiable information to third parties for such purposes. Carts Guru has adopted a policy of allowing You to opt-out of the disclosure of Your personally identifiable information to third parties for their direct marketing purposes and thus falls within this exception. Instructions for opting out can be found in the section entitled found in the Choice and Opt-Out section above. | N16: 1 | O16: You may opt-out of disclosure of Your information to third parties for direct marketing purposes | P16: 1 | Q16: Proof by existence of optout | R16: 0 | T16: However, if You want to contact Us directly about accessing, changing or deleting Your personal information, or altering Your data or marketing preferences, please email Us at privacy@carts.guru. | U16: https://www.carts.guru/privacy-policy/services-privacy-policy
A17: 295 | B17: https://www.clixtell.com/ | C17: 45233 | D17: Sophie | E17: 45529 | F17: 1 | G17: FingerprintInv | H17: 1 | I17: Improve and develop the services and content offered (including by matching them to the user on the basis of his identity); | J17: 1 | K17: Some of this data can be considered as Personal Data such as your name, IP address, email etc. All Personal Data will be stored securely and only used when necessary such as to log into your account or provide customer support | L17: 1 | M17: Clixtell’s call tracking software reveals which keywords, campaigns, and ads drive into calls and conversions. Measure all phone calls from all your marketing channels, online & offline. Watch and record your customer’s full journey from search to click and call. | N17: 0 | P17: 1 | R17: 0 | U17: https://www.clixtell.com/ https://www.clixtell.com/privacy-policy/
A18: 328 | B18: https://www.crimtan.com/ | C18: 45188 | D18: Sophie | E18: 45529 | F18: 0 | H18: 1 | I18: We will only use ID-related Data in ways that the law allows us to. Most commonly, we will use ID-related Data in the following circumstances: To provide Relevant Advertising that you have consented to receive | J18: 1 | K18: We also collect, use and share Aggregated Data such as statistical or demographic data for any purpose. Aggregated Data may be derived from ID-related Data but is not associated with an ID, and thus is not treated as personal data in law. | L18: 1 | M18: Once you consent to Relevant Advertising, when you visit the sites of our advertiser clients or sites where we serve online advertising, we associate what we learn about your visit with the ID. Here is how this works: | N18: 1 | O18: You may withdraw this consent at any time by using the button below, through a Consent Management Platform, by completing the Data Subject Request Form or by emailing dpo@crimtan.com | P18: 1 | Q18: Proof by existence of optout | R18: 0 | S18: must go through contact to get permission to opt out | U18: https://www.crimtan.com/privacy-policy/
A19: 340 | B19: http://www.datranmedia.com/ | C19: 45188 | D19: Sophie | E19: 45529 | F19: 0 | H19: 1 | I19: PulsePoint operates advertising technology, and as such, has many partners in the ad tech ecosystem that it works with in order to provide advertisements to end users of websites, Apps, and other various advertising platforms and media. | J19: 1 | K19: Personally identifiable information (“PII”) is information unique to you that may be used to directly identify you individually. We may acquire PII from our publishers, advertising partners, or other third parties, but only where we have contractually required that these third parties have obtained your consent or are otherwise legally permitted or required to disclose your PII to us | L19: 1 | M19: The CCPA defines “sale” broadly, and it may include our sharing information that we have about you, such as a cookie ID or IP address, with third party advertising partners who may use this information, on our behalf, to help us deliver advertising on the WebMD Sites as well as on third party websites. You have the right to opt- out of the sale or share of your personal information subject to certain exclusions as described below. Once we receive your request, we will not sell or share your personal information, unless an exclusion applies. We may request that you authorize the sale or sharing of your personal information after 12 months following your opt-out. | N19: 1 | O19: You have various options to opt out of our Platform for IBA/OBA. Opting out does not prevent you from seeing ads; it simply means that we will no longer collect data for the purpose of IBA/OBA | P19: 1 | Q19: Proof by existence of optout | R19: 1 | S19: Cookie name not identified | T19: The DAA and NAI opt-out tools are cookie-based. It signals your preferences to us so that we do not collect data online or deliver ads for the purpose of IBA/OBA. | U19: https://www.pulsepoint.com/legal/platform-privacy-policy#info_we_share
A20: 341 | B20: http://datonics.com/ | C20: 45233 | D20: Oliver | E20: 45529 | F20: 0 | H20: 1 | I20: "Based on this data, we may then display targeted advertisements across devices that we believe are associated" | J20: 1 | K20: "We may use your information to match it with other public and private data sources in order to enhance our records, such as appending additional information to your profile, " | L20: 1 | M20: We share the information we collect with our advertising partners so they may deliver relevant online advertisements to users. Personal Information Sales Opt-Out and Opt-In Rights. You have the right to direct us to not sell your personal information at any time (the "right to opt-out"). To exercise your right to opt-out, click here. | N20: 1 | P20: 1 | R20: 0 | U20: https://www.datonics.com/technology-privacy-policy
A21: 348 | B21: http://delivr.com/ | C21: 45233 | D21: Oliver | E21: 45529 | F21: 0 | H21: 1 | I21: "The legal basis for this use and other processing will include (as relevant): to provide you with relevant marketing communications;" | J21: 0 | L21: 0 | M21: In this context, if you are subject to CCPA, you are a Business and Delivr is your Service Provider. Your sharing of Personal Information related to your end users with Delivr, and Delivr’s collection of Personal Information related to your end users, are done to facilitate Delivr’s performance of its services that you contracted for. ... Delivr does not receive from you, and you do not pay Delivr, any monetary or other valuable consideration for making Personal Information available to Delivr. | N21: 0 | P21: 1 | R21: 0 | U21: https://delivr.com/page/710/california-consumer-privacy-act-ccpa-notice https://delivr.com/page/511/privacy-notice
A22: 362 | B22: http://www.directresponsegroup.com/ | C22: 45228 | D22: Sophie | E22: 45529 | F22: 0 | H22: 1 | I22: We use Personally Identifiable Information to customize the Site, to make appropriate service offerings | J22: 1 | K22: We may collect basic user profile information from all of our Visitors. We collect the following additional information from our Authorized Customers: the names, addresses, phone numbers and email addresses of Authorized Customers, the nature and size of the business, and the nature and size of the advertising inventory that the Authorized Customer intends to purchase or sell. | L22: 1 | M22: Personally Identifiable Information about Authorized Customers may be shared with other Authorized Customers who wish to evaluate potential transactions with other Authorized Customers. We may share aggregated information about our Visitors, including the demographics of our Visitors and Authorized Customers, with our affiliated agencies and third party vendors. We also offer the opportunity to "opt out" of receiving information or being contacted by us or by any agency acting on our behalf. | N22: 0 | O22: Visitors and Authorized Customers may opt out of receiving unsolicited information from or being contacted by us and/or our vendors and affiliated agencies by responding to emails as instructed, or by contacting us at 201 Old Country Road, Suite 204, Melville, NY 11747 | P22: 1 | R22: 0 | U22: https://www.directresponsegroup.com/privacy-policy/
A23: 368 | B23: http://doublepimp.com/ | C23: 45186 | D23: Oliver | E23: 45529 | F23: 0 | H23: 1 | I23: "Ad targeting: Cookies may be used to display relevant advertisements to visitors." | J23: 0 | L23: 1 | M23: Partner ad networks: we may share a portion of your personal data (i.e. IP address and User Agent) with other third-party ad networks or business partners who are interested in serving End-Users advertisements from their own advertisers. ... Under CCPA’s broad definition, “personal information” may also include (in addition to names, addresses, and the like) unique identifiers, IP addresses, and even inferences which may be drawn from any of the above. CCPA also defines the term “sell” broadly. Its meaning includes “renting, releasing, disclosing, disseminating, making available, [and] transferring…for monetary or other valuable consideration.” Under these broad definitions, certain transfers of information (such as IP addresses, User Agents, and combinations of these) which are necessary to operate our network could arguably be deemed a “sale” of “personal information” under CCPA. You have the right to opt out of this “sale.” For more information on how to opt out, click here. | N23: 1 | O23: You have the right to opt-out from targeted advertising. In such case, Advertisers will not be able to customize their ads based on certain behaviors or audience type and your data will not be shared with third-party ad networks. If you would like to do so, you can send us an email to dpo@twinred.com and our Support Team will redirect you to a privacy center page where you can confirm your choice. | P23: 1 | Q23: Proof by existence of optout | R23: 0 | U23: https://doublepimp.com/privacypolicy#h_2350869264351608142954940
A24: 372 | B24: https://www.drift.com/ | C24: 45215 | D24: Oliver | E24: 45529 | F24: 1 | G24: Analytics | H24: 0 | J24: 1 | K24: "we collect certain information automatically, including the type of mobile device you use, your mobile device’s unique device ID, the IP address of your mobile device, your mobile operating system, the type of mobile Internet browser you use, and your general location information as described further below." | L24: 1 | M24: In the past twelve (12) months, Drift has collected from individuals, and may have shared or sold (as defined in the CCPA), certain categories of Personal Information (as defined in the CCPA) as follows: | N24: 1 | O24: "Do Not Sell My Personal Information: https://preferences.drift.com/dont_sell" | P24: 1 | R24: 0 | S24: unclear | U24: https://www.drift.com/privacy-policy/
A25: 378 | B25: http://www.ebay.com/ | C25: 45228 | D25: Sophie | E25: 45529 | F25: 1 | G25: EmailAgg | H25: 1 | I25: On this basis, we process your data for the following purposes: Customization of page content to display the items and services you may like based on the actions you take. | J25: 1 | K25: Data about your activities and interactions with our advertising partners including data about the advertisements you were shown, how often they were shown, when and where they were shown, and whether you took any action, such as clicking on an advertisement or making a purchase. The user segment or category into which you as a user fall, for example: female, 20-49 years old, interested in sneakers. | L25: 1 | M25: We share and sell personal information under California Privacy Laws. The following Table 3.1 lists the categories of personal information that are “shared” or “sold”, and the categories of recipients who receive this information. | N25: 1 | O25: AdChoices Page | P25: 1 | R25: 1 | S25: Switch | U25: https://www.ebayinc.com/company/privacy-center/privacy-notice/state-privacy-disclosures/#california
A26: 399 | B26: http://www.etrigue.com/ | C26: 45237 | D26: Sophie | E26: 45660 | F26: 0 | H26: 1 | I26: has GDPR | J26: 1 | K26: Before we collect any personally identifiable information, we will provide an explanation for the possible use of the data. The information supplied will be used by eTrigue Corporation to respond to inquiries, supply requested information on eTrigue Corporation products and services, or track orders placed with eTrigue Corporation. | L26: 1 | M26: Authorized third parties may be utilized by eTrigue Corporation to collect, track and process such information. | N26: 0 | O26: link in emails, not available on page | P26: 1 | R26: 0 | U26: https://www.etrigue.com/trust/privacy-policy/
A27: 411 | B27: http://expo-max.com/ | C27: 45233 | D27: Oliver | E27: 45660 | F27: 0 | H27: 1 | I27: "Deliver customized content and advertising that may be of interest to you;" | J27: 1 | K27: "We collect information in the following ways: Automatically when you visit our web sites or use our products and services." | L27: 1 | M27: We collect information in the following ways: ... Via advertisement serving and tracking codes that you install on your website; Automatically when you visit our web sites or use our products and services. We use "cookies" (small files placed on your hard drive) on most of our pages to help analyze our web page flow, content and advertising, promotional effectiveness, as well as security. ... We use the information we collect in a variety of ways, including to: ... Deliver customized content and advertising that may be of interest to you; ... | N27: 0 | P27: 1 | R27: 0 | U27: http://expo-max.com/privacy/
A28: 423 | B28: https://www.nexstardigital.com/ | C28: 45233 | D28: Oliver | E28: 45660 | F28: 0 | H28: 1 | I28: " We may use Personal Information collected directly during the registration process and/or via cookies, web beacons, and other similar technologies to help us evaluate and modify existing services and features, as well as provide certain information to third parties to provide advertising that is targeted to you." | J28: 1 | K28: "We may also automatically collect information that does not directly identify you but may be considered your personal data under applicable law (“Other Information”)." | L28: 1 | M28: We do not sell your Identifiable Information without your consent. However, we do share certain Personal Information with some of our partners which may be considered a “sale” under the California Consumer Privacy Act (“CCPA”) and other similar privacy laws (collectively, “Privacy Laws”), therefore, when required by applicable Privacy Laws, we give residents the right to opt out of the sale of your Personal Information (“Opt-Out Right”). | N28: 1 | P28: 1 | R28: 0 | U28: https://www.nexstar.tv/privacy-policy/
A29: 427 | B29: http://www.flashtalking.com/ | C29: 45237 | D29: Sophie | E29: 45660 | F29: 1 | G29: Analytics | H29: 1 | I29: This helps indicate if an ad is effective for the advertiser, and helps the advertiser tailor messages, offers, recommendations, and promoted content to your preferences over time. | J29: 1 | K29: we automatically collect certain information when you access websites that incorporate our Services or otherwise interact with our Services. This information does not identify you individually, but it does reflect information about the websites and mobile apps you visit and use and how you interact with the ads we serve. | L29: 1 | M29: Flashtalking’s platform uses various technologies to collect information, including cookies, web beacons, web storage, advertising device identifiers, and similar technologies. Cookies are small data files stored on your hard drive or in device memory that help to recognize that the same device has been seen before, and where, in the context of a client’s ad campaign. This helps indicate if an ad is effective for the advertiser, and helps the advertiser tailor messages, offers, recommendations, and promoted content to your preferences over time. ... We may disclose the information we collect as follows or as otherwise described in this Privacy Policy: With our advertising and publishing clients, with respect to the performance of their online ads; ... Your choices Opting out of interest-based advertising and collection of personal information Please visit our Opt Out Page. ... California consumer disclosure and rights (CCPA/CPRA) ... Categories of Personal Information we sell We do not sell personal information. Categories of Third Parties to whom Personal Information is sold We do not sell personal information. Categories of third parties to whom information was shared for a business purpose We do not share personal information with third parties except as directed by a client on their behalf. | N29: 1 | O29: Link to opt out page | P29: 1 | R29: 0 | S29: ftcOpt | T29: it doesn't work in the console | U29: https://www.flashtalking.com/privacypolicy
A30: 439 | B30: http://www.freedom.com/ | C30: 45223 | D30: Sophie | E30: 45660 | F30: 0 | H30: 1 | I30: We may use the information that we collect from you to: ... Send you information about products or services that we think may be of interest to you; | J30: 1 | K30: We may also collect personal information about you from the following categories of sources: advertising networks, internet service providers, data analytics providers, government entities, operating systems and platforms, social networks, and data brokers. | L30: 1 | M30: Third party advertisers, including Google, may also use cookies to collect non-personally identifiable information from your browser, such as pages you visited, tools you have interacted with, the channel or method in which you arrived on our Site, etc., so that they can tailor the ads you see to your preferences and behaviors. Third party cookies may also track the number of ad impressions, other uses of ad services, and interactions with these ads. | N30: 1 | O30: To learn more about this online advertising or to opt-out of this type of advertising, please click on the following links: | P30: 1 | R30: 0 | U30: https://www.freedommortgage.com/disclosures/privacy-policy
A31: 458 | B31: https://www.geoedge.com/ | C31: 45225 | D31: Oliver | E31: 45660 | F31: 0 | H31: 1 | I31: "We use cookies and similar technologies to help personalize your experience by helping save your settings and customizations across visits and providing you targeted content and advertisements matching your interests" | J31: 1 | K31: "When you use the App and/or Site, certain information may be automatically gathered about your computer or mobile device, such as operating system, IP address, device ID, and subject to your consent as may be required under applicable law, (geo) location, as well as your browsing history and any information regarding your viewing and purchase history on our App and/or Platform." | L31: 1 | M31: We may disclose information, including Personal Data we collect from and/or about you, to our trusted service providers, business partners, affiliates, subcontractors, who may use such information to ... (3) subject to your consent as may be required under applicable law, provide to you targeted offers and advertising on both our App and/or Site, as well as on other apps, platform and sites you choose to visit. | N31: 0 | P31: 1 | R31: 0 | U31: https://www.geoedge.com/privacy-policy/
A32: 459 | B32: http://getintent.com/ | C32: 45222 | D32: Sophie | E32: 45660 | F32: 0 | H32: 1 | I32: Each bid request contains the description of the interests of the audience that is likely to see the advertisement. The Platform compares the description of the audience under the bid request with the parameters of the Client’s advertising campaign. | J32: 1 | K32: When our Clients use the Platform, they may also use their data received from other sources (not from GetIntent) and other data that identifies the Client that is collected as a result of or generated by the Client’s use of the Platform (Client Data). | L32: 1 | M32: When the Sites send to the Platform bid requests (as explained in section What we do above), these bid requests may include some information about you including IP address, unique device identifiers, and the latitude and longitude of your device when you view a Site or use an App. ... We use the data processed by the Platform for the purposes of providing the Services to the Clients, in particular to analyse and report on advertising performance: the data processed is attributed to each certain advertising campaign of the Client, so the Client can monitor the performance of its advertising campaign; to improve online advertising experience and efficiency: our Platform helps the Clients to decide which advertisement to show or whether to show it and to display the Client’s particular products in response to users’ interest; to limit advertising exposure for consumers and facilitate more relevant advertising: for this purpose, we use Cross-Device IDs; | N32: 1 | O32: To opt-out or opt-in please visit the following pages: adhigh.net, digitmate.bid, cpagen.win. | P32: 1 | R32: 1 | S32: ‘Opt-out Cookie’ | T32: The Cookie previously set your browser is deleted and replaced with the Platform ‘Opt-out Cookie’ indicating your ‘opt-out’ only. | U32: https://getintent.com/privacy/
A33: 462 | B33: https://gleam.io/ | C33: 45228 | D33: Sophie | E33: 45660 | F33: 1 | G33: FingerprintInv | H33: 1 | I33: Gleam may collect and use User's personal information for the following purposes: To improve Gleam to ensure that content is presented in the most effective manner for you and for your Device; | J33: 0 | K33: Gleam also does not collect retain or share end user information including IP addresses, unique user identifiers, or personally identifiable information gathered on sites or apps not owned by Gleam, except for the limited purpose of determining conversion rates & detecting fraud | L33: 1 | M33: Gleam offers a number of integrations with 3rd party service providers that enable Campaign Owners to send Campaign Users data from Gleam for processing: ... Sailthru ... | N33: 0 | P33: 0 | R33: 0 | U33: https://gleam.io/privacy
A34: 505 | B34: https://www.indexexchange.com/ | D34: Sophie | E34: 45660 | F34: 0 | H34: 1 | I34: device advertising IDs: unique identifiers used for advertising purposes on various devices, including mobile devices | J34: 1 | K34: The information we receive is predominantly determined by each Publisher that you interact with. We are not able to determine your name, email address, or other similarly identifying information based on the Personal Data we Process | L34: 1 | M34: We may disclose, share, or sell (collectively, Share) your Personal Data with the following partners for the purpose of delivering ads to you: Buyers: we Share your Personal Data with Buyers to source ads that may be relevant to your interest(s). | N34: 1 | O34: Opt Out link | P34: 1 | Q34: Proof by existence of opt out | R34: 1 | S34: https://optout.networkadvertising.org/?c=1 | U34: https://www.indexexchange.com/privacy/exchange-platform-privacy-policy/
A35: 507 | B35: https://www.infinity.co | C35: 45186 | D35: Oliver | E35: 45660 | F35: 0 | H35: 0 | J35: 0 | L35: 1 | M35: Infinity is an analytics provider whose software allows website owners to understand the usability of their websites and the effectiveness of their marketing (the “Services”). ... 4. Disclosure of your personal data ... We may share your personal data with: our suppliers and service providers who we use in connection with and for the purposes of providing the Services, including for example providers of cloud storage, data centres and telecommunication providers. ... In order to satisfy the California Consumer Privacy Act (“CCPA”) and other relevant legislation, we are required to provide specific information for residents of California. You should also refer to the rest of this policy, which provides the requisite detail concerning: ... where we disclose this information to third parties (see Disclosure of your information). In the preceding twelve months, we have not sold any personal information belonging to consumers. ... Cookies are small data files placed on your computer by the websites you visit and can be used to help recognise you when you return to a website. We, or third party service providers, may use cookies to, among other things, measure activity, personalise your experience, remember your viewing preferences, or track your login status when accessing our site. For some of these purposes, our cookies may be tied to personal data. | N35: 0 | O35: Not needed | P35: 0 | R35: 0 | T35: Is a call analysis site, does not deal greatly with advertising | U35: https://www.infinity.co/us/privacy-policy
A36: 513 | B36: http://www.infolinks.com/ | C36: 45230 | D36: Oliver | E36: 45660 | F36: 1 | G36: FingerprintGen | H36: 1 | I36: "Serving Ads: To allow Publisher Clients to offer advertising inventory in their Digital Properties and Media Buyers to bid on and fill that inventory with relevant ads." | J36: 1 | K36: "We use cookies and other similar tracking technologies (such as pixel tags and web or browser caches) to collect information automatically from End Users’ devices." | L36: 1 | M36: When End Users visit a Digital Property that uses our technology, we (and our partners or vendors) use and deploy tracking technologies like cookies to automatically collect certain information about the End Users and their devices. Some of this information (including, for example, unique identifiers stored in a cookie or mobile advertising IDs) may identify a computer or device and may be “personal data” in some jurisdictions, including the EU. | N36: 0 | P36: 1 | R36: 0 | U36: https://www.infolinks.com/privacy-policy/
A37: 527 | B37: http://www.interpolls.com/ | C37: 45237 | D37: Sophie | E37: 45660 | F37: 0 | H37: 1 | I37: Interpolls provides Advertisers, Agencies, Publishers and its Agents the tools and services to create and deliver advertisements (also referred to as ad-serving) that you may encounter on certain web sites, monitor the performance of those advertisements, manage ad creatives for campaigns, and deliver advertisements that most likely will be relevant and interest you. | J37: 1 | K37: When Users interact with ads generated using the Interpolls Services, we may collect information on behalf of Interpolls’ Clients. Interpolls provides promotion tools and services for clients to create, manage and deliver sweepstakes or contests to users for a chance to win or earn prizes. | L37: 0 | M37: Interpolls provides Advertisers, Agencies, Publishers and its Agents the tools and services to create and deliver advertisements (also referred to as ad-serving) that you may encounter on certain web sites, monitor the performance of those advertisements, manage ad creatives for campaigns, and deliver advertisements that most likely will be relevant and interest you. ... Interpolls is a service provider as defined by CCPA. ... Interpolls has never sold any personal information of consumers. | N37: 1 | O37: Link | P37: 1 | R37: 1 | S37: optout | U37: https://www.interpolls.com/privacy
A38: 534 | B38: http://www.iprom.si/ | C38: 45188 | D38: Sophie | E38: 45660 | F38: 0 | H38: 1 | I38: The contractual processors working with the Provider are: • E-mail messaging providers (e.g. Mailchimp and others) • Providers of online advertising solutions (e.g. Google, Facebook) | J38: 1 | K38: In accordance with the purposes defined in this Privacy Policy, the Provider collects the following personal data: • Basic user information (name and surname, address) | L38: 1 | M38: In addition, cookies can be used to serve more appropriate ads and to measure ad effectiveness. The use of cookies can help us to store information for advertising purposes, including targeted, retargeting, tailored advertising, delivery of ads and clicks and conversions based on the shown ads. | N38: 1 | O38: You can opt out from collecting and using non-personal data with managing cookies in your browser or on your device. | P38: 1 | Q38: Proof by existence of optout | R38: 0 | S38: Seems to say any cookie should be blocked, but no specific cookie is mentioned | U38: https://iprom.eu/files/2022/05/iPROM-Privacy_Policy_GDPR.pdf
A39: 540 | B39: https://www.ispot.tv/ | C39: 45237 | D39: Sophie | E39: 45660 | F39: 0 | H39: 1 | I39: We collect the categories of personal information described above for the following business or commercial purposes: providing our products and services personalizing customer experience | J39: 1 | K39: See the chart below for the categories of personal information we have collected over the preceding 12 months, the retention period for each category, and the categories of sources of the information. | L39: 1 | M39: Categories of Third Parties to Whom Information is Sold or Shared - By Category: ... advertising networks, internet service providers ... Company name sells or shares personal information to third parties. You have the right at any time to direct us not to sell or share your personal information to third parties (this right is referred to as the "Right to Opt‐out."). In addition to using the "Do Not Sell My Personal Information," link on our website or here in our privacy policy link to "Do Not Sell" form, you may submit a request to exercise your Right to Opt-out as follows: ... | N39: 0 | O39: must manually contact | P39: 1 | R39: 0
A40: 544 | B40: https://www.jellyfish.com/ | C40: 45188 | D40: Sophie | E40: 45660 | F40: 0 | H40: 1 | I40: We use this information where we have a legitimate business interest to do, for example: to get in touch with you following a request you made using a form on this website; to provide our products and services; to send you marketing emails about our services, events, or other information which we think you may find interesting. | J40: 1 | K40: Information we collect about your use of the website: Technical information (including your IP address and information related to your browser and/or device) | L40: 1 | M40: As discussed above, we provide personal information to third-party advertising providers for targeted advertising purposes, so that we can provide you with more relevant and tailored ads regarding our services, or use related advertising analytics partners to understand the effectiveness of our online ads. The disclosure of your personal information to these third parties to assist us in providing these services may be considered a “sale” of personal information or the processing/sharing of personal information for targeted advertising purposes under applicable law. | N40: 1 | O40: please use the "Do Not Sell or Share My Personal Information" link in our website footer, and follow the directions provided therein. You can also submit a request to opt out of our offline disclosures of information that are subject to applicable opt out rights by emailing us at dataprotection@jellyfish.com. | P40: 1 | Q40: Proof by existence of optout | R40: 0 | S40: must go through contact to get permission to opt out | U40: https://www.jellyfish.com/en-us/privacy-policy/ https://info.jellyfish.com/en-us/ccpa-us
...

Sheet Analytics
A1: ID | B1: Network URL [URL] | C1: Date of Analysis [DATE] | D1: Reviewer [Name] | E1: Date of Selling/Sharing (Buying/Collecting) Doublechecked by SZ [DATE] | F1: Crosslisted [0, 1] | G1: Crosslisted Category [Category Name] | H1: Targeted Advertising [0, 1] | I1: Evidence | J1: Profiling [0, 1] | K1: Evidence | L1: Selling/ Sharing (Buying/Collecting) [0, 1] | M1: Evidence | N1: Setting: To Opt Out [0, 1] | O1: Evidence | P1: Selling By Default [0, 1] | Q1: Evidence | R1: Sign of Not Selling [0, 1] | S1: What is it [Name of Tag] | T1: Evidence | U1: Relevant URL [URL] | V1: Crosslisted with Advertising + Selling [0,1] | W1: Crosslisted with Advertising + Targeted Advertising [0,1] | X1: Crosslisted with Advertising + Profiling [0,1] | Y1: Crosslisted with FingerprintGen + Selling [0,1] | Z1: Crosslisted with FingerprintGen + Targeted Advertising [0,1] | AA1: Crosslisted with FingerprintGen + Profiling [0,1]
A2: 18 | B2: http://automattic.com/ | C2: 45187 | D2: Oliver | E2: N/A | F2: 1 | G2: Advertising Content | H2: 1 | I2: "Automattic uses cookies and other technologies like pixel tags to help us identify and track visitors, usage, and access preferences for our Services, as well as track and understand email campaign effectiveness and to deliver targeted ads." | J2: 1 | K2: "We also collect some information automatically: Information from cookies & other technologies Interactions with other users’ sites Location information" | L2: 1 | M2: "To the extent that we share your information with certain advertising, marketing, or analytics vendors, this can be considered a “sale” or “share” in certain U.S. States, which you may have the right to opt out of." | N2: 1 | O2: "You can learn more about this sharing and how to opt out by clicking the “Do Not Sell My Personal Information” link in the footer of our websites, or from the settings page within our apps." | P2: 1 | Q2: Proof by existence of optout | R2: 1 | S2: In a cookie | T2: "Our opt-out is managed through cookies, so if you delete cookies, your browser is set to delete cookies automatically after a certain length of time, or if you visit sites in a different browser, you’ll need to make this selection again." | U2: https://automattic.com/privacy/ | V2: =IF(ISNUMBER(SEARCH("Advertising", G2)), IF(L2 = 1, 1, 0), "") -> 1 | W2: =IF(ISNUMBER(SEARCH("Advertising", G2)), IF(H2 = 1, 1, 0), "") -> 1 | X2: =IF(ISNUMBER(SEARCH("Advertising", G2)), IF(J2 = 1, 1, 0), "") -> 1 | Y2: =IF(ISNUMBER(SEARCH("FingerprintGen", G2)), IF(L2 = 1, 1, 0), "") | Z2: =IF(ISNUMBER(SEARCH("FingerprintGen", G2)), IF(H2 = 1, 1, 0), "") | AA2: =IF(ISNUMBER(SEARCH("FingerprintGen", G2)), IF(J2 = 1, 1, 0), "")
A3: 24 | B3: http://www.blogcounter.de/ | C3: 45188 | D3: Sophie | E3: N/A | F3: 0 | H3: 1 | I3: Advertising Cookies. Advertising Cookies are used to serve you with advertisements that may be relevant to you and your interests. | J3: 1 | K3: We may also collect information how the Service is accessed and used (“Usage Data”). This Usage Data may include information such as your computer’s Internet Protocol address (e.g. IP address), browser type, browser version, the pages of our Service that you visit, the time and date of your visit, the time spent on those pages, unique device identifiers and other diagnostic data. | L3: 0 | M3: We use your data to provide and improve the Service. By using the Service, you agree to the collection and use of information in accordance with this policy. | N3: 0 | U3: https://www.opensourcecms.com/privacy-policy/ | V3: =IF(ISNUMBER(SEARCH("Advertising", G3)), IF(L3 = 1, 1, 0), "") | W3: =IF(ISNUMBER(SEARCH("Advertising", G3)), IF(H3 = 1, 1, 0), "") | X3: =IF(ISNUMBER(SEARCH("Advertising", G3)), IF(J3 = 1, 1, 0), "") | Y3: =IF(ISNUMBER(SEARCH("FingerprintGen", G3)), IF(L3 = 1, 1, 0), "") | Z3: =IF(ISNUMBER(SEARCH("FingerprintGen", G3)), IF(H3 = 1, 1, 0), "") | AA3: =IF(ISNUMBER(SEARCH("FingerprintGen", G3)), IF(J3 = 1, 1, 0), "")
A4: 49 | B4: http://www.convert.com/ | C4: 45188 | D4: Sophie | E4: N/A | F4: 0 | H4: 1 | I4: Personalize and customize our content and to give you the best user experience and to enable you to participate in interactive features of our Website. | J4: 1 | K4: Automatic information (some of which can be personal data) about your visits to our Website which will include (but are not limited to) your IP address, online tracking such as location, browser and type of device you use and your operating system, | L4: 1 | M4: Allow authorized third parties (for a list of our authorized third parties see here) to track and store information about visitors to our website (including IP addresses). Disclose your personal data to those who are providing services to us if they have appropriate processes to protect it. | N4: 1 | O4: Our customers can place an opt-out link on their website and we respect your privacy when you turn off tracking features and other security settings in your browser. | P4: 1 | Q4: Proof by existence of optout | R4: 1 | S4: opt-out link on their website that can be used by visitors to their websites who do not want their information given to us | U4: https://www.convert.com/privacy-notice/ | V4: =IF(ISNUMBER(SEARCH("Advertising", G4)), IF(L4 = 1, 1, 0), "") | W4: =IF(ISNUMBER(SEARCH("Advertising", G4)), IF(H4 = 1, 1, 0), "") | X4: =IF(ISNUMBER(SEARCH("Advertising", G4)), IF(J4 = 1, 1, 0), "") | Y4: =IF(ISNUMBER(SEARCH("FingerprintGen", G4)), IF(L4 = 1, 1, 0), "") | Z4: =IF(ISNUMBER(SEARCH("FingerprintGen", G4)), IF(H4 = 1, 1, 0), "") | AA4: =IF(ISNUMBER(SEARCH("FingerprintGen", G4)), IF(J4 = 1, 1, 0), "")
A5: 53 | B5: https://www.crownpeak.com/ | C5: 45188 | D5: Sophie | E5: N/A | F5: 0 | H5: 1 | I5: To personalise the marketing messages we send by analysing the details of the products and services you have with us. | J5: 1 | K5: Your name, job title, contact details (e.g., phone number, email address, postal address or mobile number) and authentication details (e.g., user identification number, username, password to access the services). | L5: 1 | M5: Service providers and business partners that perform services on our behalf, including improving functionality of our platforms and websites, collecting information about you and assisting us with IT and social media management and data analytics. ... If you would like to exercise these rights please submit a request, with a description of the nature of your request and the Personal Data at issue. ... Right: In relation to automated decision-making and profiling | N5: 0 | U5: https://www.crownpeak.com/policies/privacy-policy/ | V5: =IF(ISNUMBER(SEARCH("Advertising", G5)), IF(L5 = 1, 1, 0), "") | W5: =IF(ISNUMBER(SEARCH("Advertising", G5)), IF(H5 = 1, 1, 0), "") | X5: =IF(ISNUMBER(SEARCH("Advertising", G5)), IF(J5 = 1, 1, 0), "") | Y5: =IF(ISNUMBER(SEARCH("FingerprintGen", G5)), IF(L5 = 1, 1, 0), "") | Z5: =IF(ISNUMBER(SEARCH("FingerprintGen", G5)), IF(H5 = 1, 1, 0), "") | AA5: =IF(ISNUMBER(SEARCH("FingerprintGen", G5)), IF(J5 = 1, 1, 0), "")
A6: 64 | B6: https://www.eff.org/ | C6: 45187 | D6: Oliver | E6: N/A | F6: 0 | H6: 0 | J6: 0 | L6: 0 | M6: "EFF does not sell or rent member, donor or website visitor information under any circumstances, and we do not share member, donor or visitor information without prior consent except as compelled by law." | N6: 0 | P6: 0 | R6: 0 | U6: https://www.eff.org/policy It's a site about preserving internet privacy | V6: =IF(ISNUMBER(SEARCH("Advertising", G6)), IF(L6 = 1, 1, 0), "") | W6: =IF(ISNUMBER(SEARCH("Advertising", G6)), IF(H6 = 1, 1, 0), "") | X6: =IF(ISNUMBER(SEARCH("Advertising", G6)), IF(J6 = 1, 1, 0), "") | Y6: =IF(ISNUMBER(SEARCH("FingerprintGen", G6)), IF(L6 = 1, 1, 0), "") | Z6: =IF(ISNUMBER(SEARCH("FingerprintGen", G6)), IF(H6 = 1, 1, 0), "") | AA6: =IF(ISNUMBER(SEARCH("FingerprintGen", G6)), IF(J6 = 1, 1, 0), "")
A7: 68 | B7: http://extremetracking.com/ | C7: 45188 | D7: Sophie | E7: N/A | F7: 0 | H7: 0 | J7: 1 | K7: While it's not up to us which data we receive, it typically includes items such as IP addresses and website performance data derived from browser activity. | L7: 0 | M7: None of your personal information will be disclosed to anyone without your explicit permission. | N7: 0 | U7: https://extremetracking.com/?policy | V7: =IF(ISNUMBER(SEARCH("Advertising", G7)), IF(L7 = 1, 1, 0), "") | W7: =IF(ISNUMBER(SEARCH("Advertising", G7)), IF(H7 = 1, 1, 0), "") | X7: =IF(ISNUMBER(SEARCH("Advertising", G7)), IF(J7 = 1, 1, 0), "") | Y7: =IF(ISNUMBER(SEARCH("FingerprintGen", G7)), IF(L7 = 1, 1, 0), "") | Z7: =IF(ISNUMBER(SEARCH("FingerprintGen", G7)), IF(H7 = 1, 1, 0), "") | AA7: =IF(ISNUMBER(SEARCH("FingerprintGen", G7)), IF(J7 = 1, 1, 0), "")
A8: 98 | B8: http://www.hubspot.com/ | C8: 45187 | D8: Oliver | E8: N/A | F8: 1 | G8: Email Aggressive | H8: 1 | I8: "Our ad network partner uses cookies and web beacons to collect information about your activities on this and other websites to provide you targeted advertising based upon your interests" | J8: 1 | K8: "For these purposes we do link this automatically-collected data to other personal data provided by you such as name, email address, address, and phone number." | L8: 0 | M8: "Not a Sale. The parties acknowledge and agree that the disclosure of California Personal Information by the Customer to HubSpot does not form part of any monetary or other valuable consideration exchanged between the parties." | N8: 0 | P8: 0 | R8: 0 | U8: https://legal.hubspot.com/legal-stuff https://legal.hubspot.com/dpa | V8: =IF(ISNUMBER(SEARCH("Advertising", G8)), IF(L8 = 1, 1, 0), "") | W8: =IF(ISNUMBER(SEARCH("Advertising", G8)), IF(H8 = 1, 1, 0), "") | X8: =IF(ISNUMBER(SEARCH("Advertising", G8)), IF(J8 = 1, 1, 0), "") | Y8: =IF(ISNUMBER(SEARCH("FingerprintGen", G8)), IF(L8 = 1, 1, 0), "") | Z8: =IF(ISNUMBER(SEARCH("FingerprintGen", G8)), IF(H8 = 1, 1, 0), "") | AA8: =IF(ISNUMBER(SEARCH("FingerprintGen", G8)), IF(J8 = 1, 1, 0), "")
